<?xml version="1.0"?>
<robot xmlns:xacro="http://www.ros.org/wiki/xacro">

    <material name="black">
        <color rgba="0 0 0 1"/>
    </material>
    <material name="white">
        <color rgba="1 1 1 1"/>
    </material>
    <material name="orange">
        <color rgba="1 0.3 0.1 1"/>
    </material>
    <material name="blue">
        <color rgba="0.2 0.2 1 1"/>
    </material>

    <!-- base link-->
    <link name ="base_link">

    </link>

    <!-- chassis link-->
    <joint name="chassis_joint" type="fixed">
    <origin xyz="0.15 0 0.75" rpy="0 0 0"/>
    <parent link="base_link"/>
    <child link="chassis"/>
    </joint>

    <link name="chassis">
    <visual>
        <geometry>
            <box size="0.3 0.3 0.15"/>
        </geometry>
    </visual>
    </link>

    <!-- left wheel link-->
    <joint name="left_wheel_joint" type="continuous">
        <origin xyz="0 0.175 0" rpy="-${pi/2} 0 0"/>
        <parent link="base_link"/>
        <child link="left_wheel"/>
        <axis xyz="0 0 1"/>
    </joint>  
    <link name="left_wheel">
        <visual>
            <geometry>
                <cylinder radius="0.05" length="0.04"/>
            </geometry>
        </visual>
    </link>

    <!-- right wheel link-->
    <joint name="right_wheel_joint" type="continuous">
        <origin xyz="0 -0.175 0" rpy="${pi/2} 0 0"/>
        <parent link="base_link"/>
        <child link="right_wheel"/>
        <axis xyz="0 0 -1"/>
    </joint>  
    <link name="right_wheel">
        <visual>
            <geometry>
                <cylinder radius="0.05" length="0.04"/>
            </geometry>
        </visual>
    </link>
</robot>
